Workbook

Sheet RIEPILOGO CONSUNTIVI
E3: Spett.le
B9: DIREZIONE OPERATION - AREA LOMBARDIA | E9: c.a: | F9: RIPA ANTONIO | H9: TASSINI DAVIDE
B13: DATA: | C13: 46174
B15: COMMITTENTE: RAI | F15: CONS.
B16: PRESIDIO: RAI MILANO | F16: ODL:
B17: AREA INTERVENTO: C.so Sempione 27 (MI) | F17: MANUTENZIONE EXTRA CANONE
B19: OGGETTO: RIEPILOGO CONSUNTIVI LAVORAZIONI EXTRA CANONE APRILE-MAGGIO-GIUGNO 2026
B20: COMPUTO METRICO ESTIMATIVO
B22: NUMERO RAPPORTO DI LAVORO REKEEP | E22: PREZIARIO REGIONE LOMBARDIA 2022 | H22: NUOVO PREZZO | K22: IMPORTO
B23: RAPPORTO DI LAVORO N° : 0155952/22 | E23: 0 | H23: ='APRILE NP 2026'!K33 -> 245.52875 | K23: =SUM(E23:J23) -> 245.52875 | M23: =G23*0.15 -> 0 | N23: =M23*(1-0.31) -> 0 | O23: =G23+N23 -> 0
B24: RAPPORTO DI LAVORO N° : | E24: 0 | H24: ='APRILE NP 2026'!K40 -> 0 | K24: =SUM(E24:J24) -> 0
B25: RAPPORTO DI LAVORO N°: 0155963/22 | E25: 0 | H25: ='MAGGIO NP 2026 '!K28 -> 194.76775 | K25: =SUM(E25:J25) -> 194.76775
B26: RAPPORTO DI LAVORO N°: | E26: 0 | H26: 0 | K26: =SUM(E26:J26) -> 0
B27: RAPPORTO DI LAVORO N°: | E27: 0 | H27: ='MAGGIO NP 2026 '!K35 -> 0 | K27: =SUM(E27:J27) -> 0
B28: RAPPORTO DI LAVORO N°: 0155973/22 | E28: 0 | H28: ='GIUGNO NP 2026 '!K37 -> 329.5051 | K28: =SUM(E28:J28) -> 329.5051
B29: RAPPORTO DI LAVORO N° : | E29: 0 | H29: ='GIUGNO NP 2026 '!K49 -> 0 | K29: =SUM(E29:J29) -> 0
B30: RAPPORTO DI LAVORO N° | E30: 0 | H30: ='GIUGNO NP 2026 '!K58 -> 0 | K30: =SUM(E30,H30) -> 0
J31: Totale | K31: =SUM(K23:K30) -> 769.8016

Sheet APRILE NP 2026
E3: Spett.le
B9: DIREZIONE OPERATION - AREA LOMBARDIA | E9: c.a: | F9: RIPA ANTONIO | H9: TASSINI DAVIDE
B13: DATA: | C13: 46113
B15: COMMITTENTE: RAI | F15: CONS. | G15: 46113
B16: PRESIDIO: RAI MILANO | F16: ODL:
B17: AREA INTERVENTO: C.so Sempione 27 (MI) | F17: MANUTENZIONE EXTRA CANONE
B19: OGGETTO: CONSUNTIVO LAVORAZIONI EXTRA CANONE APRILE 2026
B20: COMPUTO METRICO ESTIMATIVO | K20: IMPORTO
B21: RAPPORTO DI LAVORO N°: 0155952/22
B22: Listino | C22: Voci | D22: Descrizione sintetica delle lavorazioni | E22: U.M. | F22: Q.tà | G22: Prezzo unitario | H22: Incr. 15% contrattuale | I22: Sconto Gara 31% | J22: PU Scontato | K22: Totale
B23: nuovo prezzo | C23: sacchi extra 24_4_26 ALIM_DALI | D23: HFL75W-900-1800 DALI -ALIM DA | E23: cad | F23: 5 | G23: 44.5 | H23: =G23*0.15 -> 6.675 | I23: =H23*(1-0.31) -> 4.60575 | J23: =G23+I23 -> 49.10575 | K23: =F23*J23 -> 245.52875 | M23: =G23*0.15 -> 6.675 | N23: =M23*(1-0.31) -> 4.60575 | O23: =G23+N23 -> 49.10575
B24: nuovo prezzo | E24: m | H24: =G24*0.15 -> 0 | I24: =H24*(1-0.31) -> 0 | J24: =G24+I24 -> 0 | K24: =F24*J24 -> 0
B25: nuovo prezzo | E25: m | H25: =G25*0.15 -> 0 | I25: =H25*(1-0.31) -> 0 | J25: =G25+I25 -> 0 | K25: =F25*J25 -> 0
B26: nuovo prezzo | E26: cad | H26: =G26*0.15 -> 0 | I26: =H26*(1-0.31) -> 0 | J26: =G26+I26 -> 0 | K26: =F26*J26 -> 0
B27: nuovo prezzo | E27: m | H27: =G27*0.15 -> 0 | I27: =H27*(1-0.31) -> 0 | J27: =G27+I27 -> 0 | K27: =F27*J27 -> 0
B28: nuovo prezzo | E28: cad | H28: =G28*0.15 -> 0 | I28: =H28*(1-0.31) -> 0 | J28: =G28+I28 -> 0 | K28: =F28*J28 -> 0
B29: nuovo prezzo | E29: cad | H29: =G29*0.15 -> 0 | I29: =H29*(1-0.31) -> 0 | J29: =G29+I29 -> 0 | K29: =F29*J29 -> 0
B30: nuovo prezzo | E30: cad | H30: =G30*0.15 -> 0 | I30: =H30*(1-0.31) -> 0 | J30: =G30+I30 -> 0 | K30: =F30*J30 -> 0
B31: nuovo prezzo | E31: m | H31: =G31*0.15 -> 0 | I31: =H31*(1-0.31) -> 0 | J31: =G31+I31 -> 0 | K31: =F31*J31 -> 0
B32: nuovo prezzo | E32: cad | H32: =G32*0.15 -> 0 | I32: =H32*(1-0.31) -> 0 | J32: =G32+I32 -> 0 | K32: =F32*J32 -> 0
J33: Totale | K33: =SUM(K23:K32) -> 245.52875
B37: RAPPORTO DI LAVORO N° :
B38: Listino | C38: Voci | D38: Descrizione sintetica delle lavorazioni | E38: U.M. | F38: Q.tà | G38: Prezzo unitario | H38: Incr. 15% contrattuale | I38: Sconto Gara 31% | J38: PU Scontato | K38: Totale
B39: nuovo prezzo | E39: n. | H39: =G39*0.15 -> 0 | I39: =H39*(1-0.31) -> 0 | J39: =G39+I39 -> 0 | K39: =F39*J39 -> 0 | M39: =G39*0.15 -> 0 | N39: =M39*(1-0.31) -> 0 | O39: =G39+N39 -> 0
J40: Totale | K40: =SUM(K39:K39) -> 0
J42: Totale | K42: =SUM(K33:K40) -> 245.52875

Sheet MAGGIO NP 2026 
E3: Spett.le
B9: DIREZIONE OPERATION - AREA LOMBARDIA | E9: c.a: | F9: RIPA ANTONIO | H9: TASSINI DAVIDE
B13: DATA: | C13: 46143
B15: COMMITTENTE: RAI | F15: CONS. | G15: 46143
B16: PRESIDIO: RAI MILANO | F16: ODL:
B17: AREA INTERVENTO: C.so Sempione 27 (MI) | F17: MANUTENZIONE EXTRA CANONE
B19: OGGETTO: CONSUNTIVO LAVORAZIONI EXTRA CANONE MAGGIO 2026
B20: COMPUTO METRICO ESTIMATIVO | K20: IMPORTO
B21: ST 5313 - RAPPORTO DI LAVORO N°: 0155963/22 DEL 19/05/26
B22: Listino | C22: Voci | D22: Descrizione sintetica delle lavorazioni | E22: U.M. | F22: Q.tà | G22: Prezzo unitario | H22: Incr. 15% contrattuale | I22: Sconto Gara 31% | J22: PU Scontato | K22: Totale
B23: nuovo prezzo | C23: sacchi extracan 18-05-26-19052026091102 | D23: CSP-N 75X17 G CAN. PAVIMENTO | E23: cad | F23: 8 | G23: 13.49 | H23: =G23*0.15 -> 2.0235 | I23: =H23*(1-0.31) -> 1.396215 | J23: =G23+I23 -> 14.886215 | K23: =F23*J23 -> 119.08972 | M23: =G23*0.15 -> 2.0235 | N23: =M23*(1-0.31) -> 1.396215 | O23: =G23+N23 -> 14.886215
B24: nuovo prezzo | C24: BTICINO - BTIS2020DE SPINA 2P+T ST. FRANCO_TED ORIENT SSPAZ B - S2020DE | D24: BTICINO - BTIS2020DE SPINA 2P+T ST. FRANCO/TED ORIENT SSPAZ B - S2020DE | E24: cad | F24: 8 | G24: 2.54 | H24: =G24*0.15 -> 0.381 | I24: =H24*(1-0.31) -> 0.26289 | J24: =G24+I24 -> 2.80289 | K24: =F24*J24 -> 22.42312
B25: nuovo prezzo | C25: DDT 8046428845 - R026011615 | D25: SPINA RJ45 8P8C CAT6 SCH.FLEX | E25: cad | F25: 16 | G25: 0.41 | H25: =G25*0.15 -> 0.0615 | I25: =H25*(1-0.31) -> 0.042435 | J25: =G25+I25 -> 0.452435 | K25: =F25*J25 -> 7.23896
B26: nuovo prezzo | C26: DDT 8046489037 - R026011617 | D26: CAT6 - CABLE U/UTP LSOH 23 AWG B | E26: M | F26: 30 | G26: 0.67 | H26: =G26*0.15 -> 0.1005 | I26: =H26*(1-0.31) -> 0.069345 | J26: =G26+I26 -> 0.739345 | K26: =F26*J26 -> 22.18035
B27: nuovo prezzo | C27: SACCHI 04-02-26 extrac. ray way-05022026080203 | D27: CAVO 3G2,5 BTFS180R18 450/750V 3G2,5MMQ | E27: M | F27: 15 | G27: 1.44 | H27: =G27*0.15 -> 0.216 | I27: =H27*(1-0.31) -> 0.14904 | J27: =G27+I27 -> 1.58904 | K27: =F27*J27 -> 23.8356
J28: Totale | K28: =SUM(K23:K27) -> 194.76775
B31: COMPUTO METRICO ESTIMATIVO | K31: IMPORTO
B32: RAPPORTO DI LAVORO N°:
B33: Listino | C33: Voci | D33: Descrizione sintetica delle lavorazioni | E33: U.M. | F33: Q.tà | G33: Prezzo unitario | H33: Incr. 15% contrattuale | I33: Sconto Gara 31% | J33: PU Scontato | K33: Totale
B34: nuovo prezzo | E34: cad | H34: =G34*0.15 -> 0 | I34: =H34*(1-0.31) -> 0 | J34: =G34+I34 -> 0 | K34: =F34*J34 -> 0
J35: Totale | K35: =SUM(K34) -> 0
J41: Totale | K41: =SUM(K28:K35) -> 194.76775

Sheet GIUGNO NP 2026 
E3: Spett.le
B9: DIREZIONE OPERATION - AREA LOMBARDIA | E9: c.a: | F9: RIPA ANTONIO | H9: TASSINI DAVIDE
B13: DATA: | C13: 46174
B15: COMMITTENTE: RAI | F15: CONS. | G15: 46174
B16: PRESIDIO: RAI MILANO | F16: ODL:
B17: AREA INTERVENTO: C.so Sempione 27 (MI) | F17: MANUTENZIONE EXTRA CANONE
B19: OGGETTO: CONSUNTIVO LAVORAZIONI EXTRA CANONE GIUGNO 2026
B20: COMPUTO METRICO ESTIMATIVO | K20: IMPORTO
B21: RAPPORTO DI LAVORO N°: 0155973/22 DEL 15/06/2026
B22: Listino | C22: Voci | D22: Descrizione sintetica delle lavorazioni | E22: U.M. | F22: Q.tà | G22: Prezzo unitario | H22: Incr. 15% contrattuale | I22: Sconto Gara 31% | J22: PU Scontato | K22: Totale
B23: nuovo prezzo | C23: sonepar extr 12-06-26-alim.led corridoi | D23: ALIM. LED TENS. COSTANTE 200W 24VDC DALI | E23: cad | F23: 4 | G23: 74.65 | H23: =G23*0.15 -> 11.1975 | I23: =H23*(1-0.31) -> 7.726275 | J23: =G23+I23 -> 82.376275 | K23: =F23*J23 -> 329.5051 | M23: =G23*0.15 -> 11.1975 | N23: =M23*(1-0.31) -> 7.726275 | O23: =G23+N23 -> 82.376275
B24: nuovo prezzo | E24: cad | H24: =G24*0.15 -> 0 | I24: =H24*(1-0.31) -> 0 | J24: =G24+I24 -> 0 | K24: =F24*J24 -> 0
B25: nuovo prezzo | E25: cad | H25: =G25*0.15 -> 0 | I25: =H25*(1-0.31) -> 0 | J25: =G25+I25 -> 0 | K25: =F25*J25 -> 0
B26: nuovo prezzo | E26: cad | H26: =G26*0.15 -> 0 | I26: =H26*(1-0.31) -> 0 | J26: =G26+I26 -> 0 | K26: =F26*J26 -> 0
B27: nuovo prezzo | E27: M | H27: =G27*0.15 -> 0 | I27: =H27*(1-0.31) -> 0 | J27: =G27+I27 -> 0 | K27: =F27*J27 -> 0
B28: nuovo prezzo | E28: cad | H28: =G28*0.15 -> 0 | I28: =H28*(1-0.31) -> 0 | J28: =G28+I28 -> 0 | K28: =F28*J28 -> 0
B29: nuovo prezzo | E29: cad | H29: =G29*0.15 -> 0 | I29: =H29*(1-0.31) -> 0 | J29: =G29+I29 -> 0 | K29: =F29*J29 -> 0
B30: nuovo prezzo | E30: M | H30: =G30*0.15 -> 0 | I30: =H30*(1-0.31) -> 0 | J30: =G30+I30 -> 0 | K30: =F30*J30 -> 0
B31: nuovo prezzo | E31: cad | H31: =G31*0.15 -> 0 | I31: =H31*(1-0.31) -> 0 | J31: =G31+I31 -> 0 | K31: =F31*J31 -> 0
B32: nuovo prezzo | E32: cad | H32: =G32*0.15 -> 0 | I32: =H32*(1-0.31) -> 0 | J32: =G32+I32 -> 0 | K32: =F32*J32 -> 0
B33: nuovo prezzo | E33: M | H33: =G33*0.15 -> 0 | I33: =H33*(1-0.31) -> 0 | J33: =G33+I33 -> 0 | K33: =F33*J33 -> 0
B34: nuovo prezzo | E34: M | H34: =G34*0.15 -> 0 | I34: =H34*(1-0.31) -> 0 | J34: =G34+I34 -> 0 | K34: =F34*J34 -> 0
B35: nuovo prezzo | E35: M | H35: =G35*0.15 -> 0 | I35: =H35*(1-0.31) -> 0 | J35: =G35+I35 -> 0 | K35: =F35*J35 -> 0
B36: nuovo prezzo
J37: Totale | K37: =SUM(K23:K32) -> 329.5051
B41: RAPPORTO DI LAVORO N°
B42: Listino | C42: Voci | D42: Descrizione sintetica delle lavorazioni | E42: U.M. | F42: Q.tà | G42: Prezzo unitario | H42: Incr. 15% contrattuale | I42: Sconto Gara 31% | J42: PU Scontato | K42: Totale
B43: nuovo prezzo | E43: M | H43: =G43*0.15 -> 0 | I43: =H43*(1-0.31) -> 0 | J43: =G43+I43 -> 0 | K43: =F43*J43 -> 0 | M43: =G43*0.15 -> 0 | N43: =M43*(1-0.31) -> 0 | O43: =G43+N43 -> 0
B44: nuovo prezzo | E44: cad | H44: =G44*0.15 -> 0 | I44: =H44*(1-0.31) -> 0 | J44: =G44+I44 -> 0 | K44: =F44*J44 -> 0
B45: nuovo prezzo | E45: cad | H45: =G45*0.15 -> 0 | I45: =H45*(1-0.31) -> 0 | J45: =G45+I45 -> 0 | K45: =F45*J45 -> 0
B46: nuovo prezzo | E46: M | H46: =G46*0.15 -> 0 | I46: =H46*(1-0.31) -> 0 | J46: =G46+I46 -> 0 | K46: =F46*J46 -> 0
B47: nuovo prezzo | E47: cad | H47: =G47*0.15 -> 0 | I47: =H47*(1-0.31) -> 0 | J47: =G47+I47 -> 0 | K47: =F47*J47 -> 0
B48: nuovo prezzo | E48: M | H48: =G48*0.15 -> 0 | I48: =H48*(1-0.31) -> 0 | J48: =G48+I48 -> 0 | K48: =F48*J48 -> 0
J49: Totale | K49: =SUM(K43:K48) -> 0
B52: RAPPORTO DI LAVORO N°
B53: Listino | C53: Voci | D53: Descrizione sintetica delle lavorazioni | E53: U.M. | F53: Q.tà | G53: Prezzo unitario | H53: Incr. 15% contrattuale | I53: Sconto Gara 31% | J53: PU Scontato | K53: Totale
B54: nuovo prezzo | E54: cad | H54: =G54*0.15 -> 0 | I54: =H54*(1-0.31) -> 0 | J54: =G54+I54 -> 0 | K54: =F54*J54 -> 0
B55: nuovo prezzo | E55: M | H55: =G55*0.15 -> 0 | I55: =H55*(1-0.31) -> 0 | J55: =G55+I55 -> 0 | K55: =F55*J55 -> 0
B56: nuovo prezzo | E56: M | H56: =G56*0.15 -> 0 | I56: =H56*(1-0.31) -> 0 | J56: =G56+I56 -> 0 | K56: =F56*J56 -> 0
B57: nuovo prezzo | E57: cad | H57: =G57*0.15 -> 0 | I57: =H57*(1-0.31) -> 0 | J57: =G57+I57 -> 0 | K57: =F57*J57 -> 0
...
